Workbook

Sheet Summary
A1: PLASMAIDE — Annual P&L Summary (Multi-Channel)
A2: Australian Financial Year (Jul–Jun)
B4: FY26 | C4: FY27 | D4: FY28 | E4: FY29 | F4: FY30 | G4: 5-Year Total
A6: REVENUE BY CHANNEL
A7: DTC Revenue | B7: =SUM('P&L'!B7:M7) -> 945274 | C7: =SUM('P&L'!N7:Y7) -> 3440934 | D7: =SUM('P&L'!Z7:AK7) -> 7749378 | E7: =SUM('P&L'!AL7:AW7) -> 14601510 | F7: =SUM('P&L'!AX7:BI7) -> 26655552 | G7: =SUM(B7:F7) -> 53392648
A8: Wholesale Revenue | B8: =SUM('P&L'!B8:M8) -> 157207 | C8: =SUM('P&L'!N8:Y8) -> 217728 | D8: =SUM('P&L'!Z8:AK8) -> 290304 | E8: =SUM('P&L'!AL8:AW8) -> 362880 | F8: =SUM('P&L'!AX8:BI8) -> 435456 | G8: =SUM(B8:F8) -> 1463575
A9: Retail Revenue | B9: =SUM('P&L'!B9:M9) -> 0 | C9: =SUM('P&L'!N9:Y9) -> 0 | D9: =SUM('P&L'!Z9:AK9) -> 0 | E9: =SUM('P&L'!AL9:AW9) -> 172368 | F9: =SUM('P&L'!AX9:BI9) -> 438858 | G9: =SUM(B9:F9) -> 611226
A10: Total Net Revenue | B10: =SUM('P&L'!B10:M10) -> 1102481 | C10: =SUM('P&L'!N10:Y10) -> 3658662 | D10: =SUM('P&L'!Z10:AK10) -> 8039682 | E10: =SUM('P&L'!AL10:AW10) -> 15136758 | F10: =SUM('P&L'!AX10:BI10) -> 27529866 | G10: =SUM(B10:F10) -> 55467449
A12: COST OF GOODS SOLD
A13: Product Cost | B13: =SUM('P&L'!B13:M13) -> 275620.25 | C13: =SUM('P&L'!N13:Y13) -> 914665.5 | D13: =SUM('P&L'!Z13:AK13) -> 2009920.5 | E13: =SUM('P&L'!AL13:AW13) -> 3784189.5 | F13: =SUM('P&L'!AX13:BI13) -> 6882466.5 | G13: =SUM(B13:F13) -> 13866862
A14: Fulfillment | B14: =SUM('P&L'!B14:M14) -> 87064 | C14: =SUM('P&L'!N14:Y14) -> 330108 | D14: =SUM('P&L'!Z14:AK14) -> 741236 | E14: =SUM('P&L'!AL14:AW14) -> 1396924 | F14: =SUM('P&L'!AX14:BI14) -> 2549256 | G14: =SUM(B14:F14) -> 5104588
A15: Transaction Fees | B15: =SUM('P&L'!B15:M15) -> 28358.22 | C15: =SUM('P&L'!N15:Y15) -> 103228.02 | D15: =SUM('P&L'!Z15:AK15) -> 232481.34 | E15: =SUM('P&L'!AL15:AW15) -> 438045.3 | F15: =SUM('P&L'!AX15:BI15) -> 799666.56 | G15: =SUM(B15:F15) -> 1601779.4
A16: Total COGS | B16: =SUM('P&L'!B16:M16) -> 391042.47 | C16: =SUM('P&L'!N16:Y16) -> 1348001.5 | D16: =SUM('P&L'!Z16:AK16) -> 2983637.8 | E16: =SUM('P&L'!AL16:AW16) -> 5619158.8 | F16: =SUM('P&L'!AX16:BI16) -> 10231389 | G16: =SUM(B16:F16) -> 20573230
A18: GROSS PROFIT | B18: =SUM('P&L'!B18:M18) -> 711438.53 | C18: =SUM('P&L'!N18:Y18) -> 2310660.5 | D18: =SUM('P&L'!Z18:AK18) -> 5056044.2 | E18: =SUM('P&L'!AL18:AW18) -> 9517599.2 | F18: =SUM('P&L'!AX18:BI18) -> 17298477 | G18: =SUM(B18:F18) -> 34894219
A19: Gross Margin % | B19: =IF(B10=0,0,B18/B10) -> 0.64530684 | C19: =IF(C10=0,0,C18/C10) -> 0.63155888 | D19: =IF(D10=0,0,D18/D10) -> 0.62888609 | E19: =IF(E10=0,0,E18/E10) -> 0.62877396 | F19: =IF(F10=0,0,F18/F10) -> 0.62835311 | G19: =IF(G10=0,0,G18/G10) -> 0.62909364
A21: OPERATING EXPENSES
A22: Performance Marketing | B22: =SUM('P&L'!B22:M22) -> 53050 | C22: =SUM('P&L'!N22:Y22) -> 368521.27 | D22: =SUM('P&L'!Z22:AK22) -> 661811.26 | E22: =SUM('P&L'!AL22:AW22) -> 1188517.9 | F22: =SUM('P&L'!AX22:BI22) -> 2134407.4 | G22: =SUM(B22:F22) -> 4406307.9
A23: Brand Marketing | B23: =SUM('P&L'!B23:M23) -> 180000 | C23: =SUM('P&L'!N23:Y23) -> 198000 | D23: =SUM('P&L'!Z23:AK23) -> 217800 | E23: =SUM('P&L'!AL23:AW23) -> 239580 | F23: =SUM('P&L'!AX23:BI23) -> 263538 | G23: =SUM(B23:F23) -> 1098918
A24: Salaries & Wages | B24: =SUM('P&L'!B24:M24) -> 120000 | C24: =SUM('P&L'!N24:Y24) -> 600000 | D24: =SUM('P&L'!Z24:AK24) -> 1200000 | E24: =SUM('P&L'!AL24:AW24) -> 2400000 | F24: =SUM('P&L'!AX24:BI24) -> 4800000 | G24: =SUM(B24:F24) -> 9120000
A25: R&D / Clinical Testing | B25: =SUM('P&L'!B25:M25) -> 12000 | C25: =SUM('P&L'!N25:Y25) -> 13200 | D25: =SUM('P&L'!Z25:AK25) -> 14520 | E25: =SUM('P&L'!AL25:AW25) -> 15972 | F25: =SUM('P&L'!AX25:BI25) -> 17569.2 | G25: =SUM(B25:F25) -> 73261.2
A26: General & Admin | B26: =SUM('P&L'!B26:M26) -> 96000 | C26: =SUM('P&L'!N26:Y26) -> 100800 | D26: =SUM('P&L'!Z26:AK26) -> 105840 | E26: =SUM('P&L'!AL26:AW26) -> 111132 | F26: =SUM('P&L'!AX26:BI26) -> 116688.6 | G26: =SUM(B26:F26) -> 530460.6
A27: Platform & Technology | B27: =SUM('P&L'!B27:M27) -> 60000 | C27: =SUM('P&L'!N27:Y27) -> 63000 | D27: =SUM('P&L'!Z27:AK27) -> 66150 | E27: =SUM('P&L'!AL27:AW27) -> 69457.5 | F27: =SUM('P&L'!AX27:BI27) -> 72930.375 | G27: =SUM(B27:F27) -> 331537.88
A28: Wholesale Sales Cost | B28: =SUM('P&L'!B28:M28) -> 60000 | C28: =SUM('P&L'!N28:Y28) -> 60000 | D28: =SUM('P&L'!Z28:AK28) -> 60000 | E28: =SUM('P&L'!AL28:AW28) -> 60000 | F28: =SUM('P&L'!AX28:BI28) -> 60000 | G28: =SUM(B28:F28) -> 300000
A29: Retail Sales Cost | B29: =SUM('P&L'!B29:M29) -> 0 | C29: =SUM('P&L'!N29:Y29) -> 0 | D29: =SUM('P&L'!Z29:AK29) -> 0 | E29: =SUM('P&L'!AL29:AW29) -> 180000 | F29: =SUM('P&L'!AX29:BI29) -> 180000 | G29: =SUM(B29:F29) -> 360000
A30: Depreciation | B30: =SUM('P&L'!B30:M30) -> 6000 | C30: =SUM('P&L'!N30:Y30) -> 6000 | D30: =SUM('P&L'!Z30:AK30) -> 6000 | E30: =SUM('P&L'!AL30:AW30) -> 6000 | F30: =SUM('P&L'!AX30:BI30) -> 6000 | G30: =SUM(B30:F30) -> 30000
A31: Total Operating Expenses | B31: =SUM('P&L'!B32:M32) -> 587050 | C31: =SUM('P&L'!N32:Y32) -> 1409521.3 | D31: =SUM('P&L'!Z32:AK32) -> 2332121.3 | E31: =SUM('P&L'!AL32:AW32) -> 4270659.4 | F31: =SUM('P&L'!AX32:BI32) -> 7651133.6 | G31: =SUM(B31:F31) -> 16250486
A33: EBITDA | B33: =SUM('P&L'!B34:M34) -> 130388.53 | C33: =SUM('P&L'!N34:Y34) -> 907139.21 | D33: =SUM('P&L'!Z34:AK34) -> 2729922.9 | E33: =SUM('P&L'!AL34:AW34) -> 5252939.8 | F33: =SUM('P&L'!AX34:BI34) -> 9653343.3 | G33: =SUM(B33:F33) -> 18673734
A34: EBITDA Margin % | B34: =IF(B10=0,0,B33/B10) -> 0.11826828 | C34: =IF(C10=0,0,C33/C10) -> 0.24794288 | D34: =IF(D10=0,0,D33/D10) -> 0.33955608 | E34: =IF(E10=0,0,E33/E10) -> 0.34703202 | F34: =IF(F10=0,0,F33/F10) -> 0.35064985 | G34: =IF(G10=0,0,G33/G10) -> 0.33666112
A36: EBIT | B36: =SUM('P&L'!B37:M37) -> 124388.53 | C36: =SUM('P&L'!N37:Y37) -> 901139.21 | D36: =SUM('P&L'!Z37:AK37) -> 2723922.9 | E36: =SUM('P&L'!AL37:AW37) -> 5246939.8 | F36: =SUM('P&L'!AX37:BI37) -> 9647343.3 | G36: =SUM(B36:F36) -> 18643734
A37: Tax | B37: =SUM('P&L'!B38:M38) -> 49661.617 | C37: =SUM('P&L'!N38:Y38) -> 231168.02 | D37: =SUM('P&L'!Z38:AK38) -> 680980.73 | E37: =SUM('P&L'!AL38:AW38) -> 1311734.9 | F37: =SUM('P&L'!AX38:BI38) -> 2411835.8 | G37: =SUM(B37:F37) -> 4685381.1
A39: NET INCOME | B39: =SUM('P&L'!B40:M40) -> 74726.912 | C39: =SUM('P&L'!N40:Y40) -> 669971.19 | D39: =SUM('P&L'!Z40:AK40) -> 2042942.2 | E39: =SUM('P&L'!AL40:AW40) -> 3935204.8 | F39: =SUM('P&L'!AX40:BI40) -> 7235507.5 | G39: =SUM(B39:F39) -> 13958353
A40: Net Margin % | B40: =IF(B10=0,0,B39/B10) -> 0.067780681 | C40: =IF(C10=0,0,C39/C10) -> 0.18311918 | D40: =IF(D10=0,0,D39/D10) -> 0.25410734 | E40: =IF(E10=0,0,E39/E10) -> 0.25997673 | F40: =IF(F10=0,0,F39/F10) -> 0.26282393 | G40: =IF(G10=0,0,G39/G10) -> 0.25164944
A42: YEAR-ON-YEAR GROWTH
A43: Revenue Growth % | B43: — | C43: =IF(B10=0,0,(C10-B10)/B10) -> 2.3185715 | D43: =IF(C10=0,0,(D10-C10)/C10) -> 1.1974378 | E43: =IF(D10=0,0,(E10-D10)/D10) -> 0.88275581 | F43: =IF(E10=0,0,(F10-E10)/E10) -> 0.81874256
A44: Net Income Growth % | B44: — | C44: =IF(B39=0,0,(C39-B39)/B39) -> 7.9655944 | D44: =IF(C39=0,0,(D39-C39)/C39) -> 2.0492985 | E44: =IF(D39=0,0,(E39-D39)/D39) -> 0.92624386 | F44: =IF(E39=0,0,(F39-E39)/E39) -> 0.83866096

Sheet Drivers & Assumptions
B1: PLASMAIDE — 3-Way Integrated Financial Model (Multi-Channel)
B2: Drivers & Assumptions Dashboard
B3: Australian Financial Year (1 Jul – 30 Jun) | Monthly for 5 Years
B5: DTC (DIRECT-TO-CONSUMER) ASSUMPTIONS | C5: Value | D5: Rationale / Source
B6: DTC Average Order Value (AOV) | C6: 126 | D6: 2×14-pack sachet bundle list price
B7: DTC Customer Acquisition Cost (CAC) | C7: 40 | D7: Blended paid channel CAC for AU/UK markets
B8: Subscription Split (% of New Customers) | C8: 0.4 | D8: 40% subscribe; 60% one-off
B9: Monthly Subscription Churn Rate | C9: 0.1 | D9: Performance supplements with tangible results tracking
B10: One-off Repeat Purchase Rate (monthly) | C10: 0.05 | D10: 5% of one-off pool repurchases each month
B11: Initial Monthly Ad Spend | C11: 20000 | D11: Starting performance marketing budget
B12: Ad Spend Monthly Growth Rate | C12: 0.05 | D12: 5% monthly increase as brand scales
B13: DTC Fulfillment per Order | C13: 12 | D13: Pick-and-pack + shipping
B14: DTC Transaction Fee % | C14: 0.03 | D14: Shopify / payment gateway 3%
B15: DTC COGS % (product cost) | C15: 0.25 | D15: 70% gross margin on product cost; Pine Bark extract
B16: DTC AR Days | C16: 3 | D16: Mostly instant DTC settlement
B18: WHOLESALE ASSUMPTIONS | C18: Value | D18: Rationale / Source
B19: Wholesale Price per 14-pack | C19: 37.8 | D19: ~48% discount off DTC list for distributors
B20: Units per Case | C20: 12 | D20: 12 × 14-packs per case
B21: Cases per Pallet | C21: 36 | D21: 36 cases = 432 units per pallet
B22: Wholesale COGS % (product cost) | C22: 0.25 | D22: Same manufacturing cost base as DTC
B23: Wholesale Fulfillment per Case | C23: 5 | D23: Bulk palletised shipping — lower per unit
B24: Wholesale Transaction Fee % | C24: 0 | D24: Bank transfer / invoice — no gateway fee
B25: Wholesale AR Days | C25: 30 | D25: Standard distributor invoice terms
B26: Wholesale Order Frequency (months) | C26: 3 | D26: Quarterly ordering cycle (adjustable)
B27: Avg Cases per Order (new country, Year 1) | C27: 5 | D27: Initial trial orders — small case quantities
B28: Avg Cases per Order Growth (annual) | C28: 0.25 | D28: 25% annual increase in avg order size
B30: RETAIL ASSUMPTIONS | C30: Value | D30: Rationale / Source
B31: Retail Launch Month (month # from Jul-25) | C31: 37 | D31: Month 37 = Jul-28. Change to move launch date.
B32: Retail Price per 14-pack | C32: 37.8 | D32: ~13% discount off DTC list for retail margin sharing
B33: Retail COGS % (product cost) | C33: 0.25 | D33: Same manufacturing cost base
B34: Retail Fulfillment per Case | C34: 6 | D34: Delivery to retail stores / warehouses
B35: Retail Transaction Fee % | C35: 0 | D35: 1.5% — lower rate on B2B invoicing
B36: Retail AR Days | C36: 45 | D36: Retail chain payment terms
B37: Initial Retail Doors (stores) | C37: 20 | D37: Starting retail footprint at launch
B38: New Doors per Month (post-launch) | C38: 5 | D38: Gradual retail rollout
B39: Avg Units per Door per Month | C39: 8 | D39: 8 × 14-packs per store per month
B40: Units per Door Annual Growth | C40: 0.1 | D40: 10% annual increase as brand gains traction
B42: SHARED MARKETING & BRAND | C42: Value | D42: Rationale / Source
B43: Fixed Brand Spend (monthly) | C43: 15000 | D43: Content, influencers, partnerships
B44: Brand Spend Annual Escalation | C44: 0.1 | D44: 10% annual increase
...

Sheet DTC Revenue
A1: PLASMAIDE — DTC Revenue Build
A2: Shopify Direct-to-Consumer Channel
B4: Jul-25 | C4: Aug-25 | D4: Sep-25 | E4: Oct-25 | F4: Nov-25 | G4: Dec-25 | H4: Jan-26 | I4: Feb-26 | J4: Mar-26 | K4: Apr-26 | L4: May-26 | M4: Jun-26 | N4: Jul-26 | O4: Aug-26 | P4: Sep-26 | Q4: Oct-26 | R4: Nov-26 | S4: Dec-26 | T4: Jan-27 | U4: Feb-27 | V4: Mar-27 | W4: Apr-27 | X4: May-27 | Y4: Jun-27 | Z4: Jul-27 | AA4: Aug-27 | AB4: Sep-27 | AC4: Oct-27 | AD4: Nov-27 | AE4: Dec-27 | AF4: Jan-28 | AG4: Feb-28 | AH4: Mar-28 | AI4: Apr-28 | AJ4: May-28 | AK4: Jun-28 | AL4: Jul-28 | AM4: Aug-28 | AN4: Sep-28 | AO4: Oct-28 | AP4: Nov-28 | AQ4: Dec-28 | AR4: Jan-29 | AS4: Feb-29 | AT4: Mar-29 | AU4: Apr-29 | AV4: May-29 | AW4: Jun-29 | AX4: Jul-29 | AY4: Aug-29 | AZ4: Sep-29 | BA4: Oct-29 | BB4: Nov-29 | BC4: Dec-29 | BD4: Jan-30 | BE4: Feb-30 | BF4: Mar-30 | BG4: Apr-30 | BH4: May-30 | BI4: Jun-30
A6: DTC ACTUALS (AUD)
A7: DTC Revenue (Actuals) | B7: 37954 | C7: 61361 | D7: 108804 | E7: 57522 | F7: 71229 | G7: 61780 | H7: 62159 | I7: 181457 | J7: 50000
A8: Implied Orders (Actuals ÷ AOV) | B8: =ROUND(B7/'Drivers & Assumptions'!C6,0) -> 301 | C8: =ROUND(C7/'Drivers & Assumptions'!C6,0) -> 487 | D8: =ROUND(D7/'Drivers & Assumptions'!C6,0) -> 864 | E8: =ROUND(E7/'Drivers & Assumptions'!C6,0) -> 457 | F8: =ROUND(F7/'Drivers & Assumptions'!C6,0) -> 565 | G8: =ROUND(G7/'Drivers & Assumptions'!C6,0) -> 490 | H8: =ROUND(H7/'Drivers & Assumptions'!C6,0) -> 493 | I8: =ROUND(I7/'Drivers & Assumptions'!C6,0) -> 1440
A10: AD SPEND & ACQUISITION
A11: Monthly Performance Ad Spend | B11: 0 | C11: =B11*(1+'Drivers & Assumptions'!C12) -> 0 | D11: =C11*(1+'Drivers & Assumptions'!C12) -> 0 | E11: =D11*(1+'Drivers & Assumptions'!C12) -> 0 | F11: =E11*(1+'Drivers & Assumptions'!C12) -> 0 | G11: =F11*(1+'Drivers & Assumptions'!C12) -> 0 | H11: =G11*(1+'Drivers & Assumptions'!C12) -> 0 | I11: =H11*(1+'Drivers & Assumptions'!C12) -> 0 | J11: 0 | K11: 10000 | L11: ='Drivers & Assumptions'!C11*(1+'Drivers & Assumptions'!C12) -> 21000 | M11: =L11*(1+'Drivers & Assumptions'!C12) -> 22050 | N11: =M11*(1+'Drivers & Assumptions'!C12) -> 23152.5 | O11: =N11*(1+'Drivers & Assumptions'!C12) -> 24310.125 | P11: =O11*(1+'Drivers & Assumptions'!C12) -> 25525.631 | Q11: =P11*(1+'Drivers & Assumptions'!C12) -> 26801.913 | R11: =Q11*(1+'Drivers & Assumptions'!C12) -> 28142.008 | S11: =R11*(1+'Drivers & Assumptions'!C12) -> 29549.109 | T11: =S11*(1+'Drivers & Assumptions'!C12) -> 31026.564 | U11: =T11*(1+'Drivers & Assumptions'!C12) -> 32577.893 | V11: =U11*(1+'Drivers & Assumptions'!C12) -> 34206.787 | W11: =V11*(1+'Drivers & Assumptions'!C12) -> 35917.127 | X11: =W11*(1+'Drivers & Assumptions'!C12) -> 37712.983 | Y11: =X11*(1+'Drivers & Assumptions'!C12) -> 39598.632 | Z11: =Y11*(1+'Drivers & Assumptions'!C12) -> 41578.564 | AA11: =Z11*(1+'Drivers & Assumptions'!C12) -> 43657.492 | AB11: =AA11*(1+'Drivers & Assumptions'!C12) -> 45840.366 | AC11: =AB11*(1+'Drivers & Assumptions'!C12) -> 48132.385 | AD11: =AC11*(1+'Drivers & Assumptions'!C12) -> 50539.004 | AE11: =AD11*(1+'Drivers & Assumptions'!C12) -> 53065.954 | AF11: =AE11*(1+'Drivers & Assumptions'!C12) -> 55719.252 | AG11: =AF11*(1+'Drivers & Assumptions'!C12) -> 58505.214 | AH11: =AG11*(1+'Drivers & Assumptions'!C12) -> 61430.475 | AI11: =AH11*(1+'Drivers & Assumptions'!C12) -> 64501.999 | AJ11: =AI11*(1+'Drivers & Assumptions'!C12) -> 67727.099 | AK11: =AJ11*(1+'Drivers & Assumptions'!C12) -> 71113.454 | AL11: =AK11*(1+'Drivers & Assumptions'!C12) -> 74669.126 | AM11: =AL11*(1+'Drivers & Assumptions'!C12) -> 78402.583 | AN11: =AM11*(1+'Drivers & Assumptions'!C12) -> 82322.712 | AO11: =AN11*(1+'Drivers & Assumptions'!C12) -> 86438.848 | AP11: =AO11*(1+'Drivers & Assumptions'!C12) -> 90760.79 | AQ11: =AP11*(1+'Drivers & Assumptions'!C12) -> 95298.829 | AR11: =AQ11*(1+'Drivers & Assumptions'!C12) -> 100063.77 | AS11: =AR11*(1+'Drivers & Assumptions'!C12) -> 105066.96 | AT11: =AS11*(1+'Drivers & Assumptions'!C12) -> 110320.31 | AU11: =AT11*(1+'Drivers & Assumptions'!C12) -> 115836.32 | AV11: =AU11*(1+'Drivers & Assumptions'!C12) -> 121628.14 | AW11: =AV11*(1+'Drivers & Assumptions'!C12) -> 127709.55 | AX11: =AW11*(1+'Drivers & Assumptions'!C12) -> 134095.02 | AY11: =AX11*(1+'Drivers & Assumptions'!C12) -> 140799.77 | AZ11: =AY11*(1+'Drivers & Assumptions'!C12) -> 147839.76 | BA11: =AZ11*(1+'Drivers & Assumptions'!C12) -> 155231.75 | BB11: =BA11*(1+'Drivers & Assumptions'!C12) -> 162993.34 | BC11: =BB11*(1+'Drivers & Assumptions'!C12) -> 171143.01 | BD11: =BC11*(1+'Drivers & Assumptions'!C12) -> 179700.16 | BE11: =BD11*(1+'Drivers & Assumptions'!C12) -> 188685.16 | BF11: =BE11*(1+'Drivers & Assumptions'!C12) -> 198119.42 | BG11: =BF11*(1+'Drivers & Assumptions'!C12) -> 208025.39 | BH11: =BG11*(1+'Drivers & Assumptions'!C12) -> 218426.66 | BI11: =BH11*(1+'Drivers & Assumptions'!C12) -> 229348
A12: New Customers (Ad Spend ÷ CAC) | B12: =ROUND(B11/'Drivers & Assumptions'!C7,0) -> 0 | C12: =ROUND(C11/'Drivers & Assumptions'!C7,0) -> 0 | D12: =ROUND(D11/'Drivers & Assumptions'!C7,0) -> 0 | E12: =ROUND(E11/'Drivers & Assumptions'!C7,0) -> 0 | F12: =ROUND(F11/'Drivers & Assumptions'!C7,0) -> 0 | G12: =ROUND(G11/'Drivers & Assumptions'!C7,0) -> 0 | H12: =ROUND(H11/'Drivers & Assumptions'!C7,0) -> 0 | I12: =ROUND(I11/'Drivers & Assumptions'!C7,0) -> 0 | J12: =ROUND(J11/'Drivers & Assumptions'!C7,0) -> 0 | K12: =ROUND(K11/'Drivers & Assumptions'!C7,0) -> 250 | L12: =ROUND(L11/'Drivers & Assumptions'!C7,0) -> 525 | M12: =ROUND(M11/'Drivers & Assumptions'!C7,0) -> 551 | N12: =ROUND(N11/'Drivers & Assumptions'!C7,0) -> 579 | O12: =ROUND(O11/'Drivers & Assumptions'!C7,0) -> 608 | P12: =ROUND(P11/'Drivers & Assumptions'!C7,0) -> 638 | Q12: =ROUND(Q11/'Drivers & Assumptions'!C7,0) -> 670 | R12: =ROUND(R11/'Drivers & Assumptions'!C7,0) -> 704 | S12: =ROUND(S11/'Drivers & Assumptions'!C7,0) -> 739 | T12: =ROUND(T11/'Drivers & Assumptions'!C7,0) -> 776 | U12: =ROUND(U11/'Drivers & Assumptions'!C7,0) -> 814 | V12: =ROUND(V11/'Drivers & Assumptions'!C7,0) -> 855 | W12: =ROUND(W11/'Drivers & Assumptions'!C7,0) -> 898 | X12: =ROUND(X11/'Drivers & Assumptions'!C7,0) -> 943 | Y12: =ROUND(Y11/'Drivers & Assumptions'!C7,0) -> 990 | Z12: =ROUND(Z11/'Drivers & Assumptions'!C7,0) -> 1039 | AA12: =ROUND(AA11/'Drivers & Assumptions'!C7,0) -> 1091 | AB12: =ROUND(AB11/'Drivers & Assumptions'!C7,0) -> 1146 | AC12: =ROUND(AC11/'Drivers & Assumptions'!C7,0) -> 1203 | AD12: =ROUND(AD11/'Drivers & Assumptions'!C7,0) -> 1263 | AE12: =ROUND(AE11/'Drivers & Assumptions'!C7,0) -> 1327 | AF12: =ROUND(AF11/'Drivers & Assumptions'!C7,0) -> 1393 | AG12: =ROUND(AG11/'Drivers & Assumptions'!C7,0) -> 1463 | AH12: =ROUND(AH11/'Drivers & Assumptions'!C7,0) -> 1536 | AI12: =ROUND(AI11/'Drivers & Assumptions'!C7,0) -> 1613 | AJ12: =ROUND(AJ11/'Drivers & Assumptions'!C7,0) -> 1693 | AK12: =ROUND(AK11/'Drivers & Assumptions'!C7,0) -> 1778 | AL12: =ROUND(AL11/'Drivers & Assumptions'!C7,0) -> 1867 | AM12: =ROUND(AM11/'Drivers & Assumptions'!C7,0) -> 1960 | AN12: =ROUND(AN11/'Drivers & Assumptions'!C7,0) -> 2058 | AO12: =ROUND(AO11/'Drivers & Assumptions'!C7,0) -> 2161 | AP12: =ROUND(AP11/'Drivers & Assumptions'!C7,0) -> 2269 | AQ12: =ROUND(AQ11/'Drivers & Assumptions'!C7,0) -> 2382 | AR12: =ROUND(AR11/'Drivers & Assumptions'!C7,0) -> 2502 | AS12: =ROUND(AS11/'Drivers & Assumptions'!C7,0) -> 2627 | AT12: =ROUND(AT11/'Drivers & Assumptions'!C7,0) -> 2758 | AU12: =ROUND(AU11/'Drivers & Assumptions'!C7,0) -> 2896 | AV12: =ROUND(AV11/'Drivers & Assumptions'!C7,0) -> 3041 | AW12: =ROUND(AW11/'Drivers & Assumptions'!C7,0) -> 3193 | AX12: =ROUND(AX11/'Drivers & Assumptions'!C7,0) -> 3352 | AY12: =ROUND(AY11/'Drivers & Assumptions'!C7,0) -> 3520 | AZ12: =ROUND(AZ11/'Drivers & Assumptions'!C7,0) -> 3696 | BA12: =ROUND(BA11/'Drivers & Assumptions'!C7,0) -> 3881 | BB12: =ROUND(BB11/'Drivers & Assumptions'!C7,0) -> 4075 | BC12: =ROUND(BC11/'Drivers & Assumptions'!C7,0) -> 4279 | BD12: =ROUND(BD11/'Drivers & Assumptions'!C7,0) -> 4493 | BE12: =ROUND(BE11/'Drivers & Assumptions'!C7,0) -> 4717 | BF12: =ROUND(BF11/'Drivers & Assumptions'!C7,0) -> 4953 | BG12: =ROUND(BG11/'Drivers & Assumptions'!C7,0) -> 5201 | BH12: =ROUND(BH11/'Drivers & Assumptions'!C7,0) -> 5461 | BI12: =ROUND(BI11/'Drivers & Assumptions'!C7,0) -> 5734
A14: CUSTOMER COHORT MODEL
A15: New Subscribers | J15: 6 | K15: =ROUND(K12*'Drivers & Assumptions'!C8,0) -> 100 | L15: =ROUND(L12*'Drivers & Assumptions'!C8,0) -> 210 | M15: =ROUND(M12*'Drivers & Assumptions'!C8,0) -> 220 | N15: =ROUND(N12*'Drivers & Assumptions'!C8,0) -> 232 | O15: =ROUND(O12*'Drivers & Assumptions'!C8,0) -> 243 | P15: =ROUND(P12*'Drivers & Assumptions'!C8,0) -> 255 | Q15: =ROUND(Q12*'Drivers & Assumptions'!C8,0) -> 268 | R15: =ROUND(R12*'Drivers & Assumptions'!C8,0) -> 282 | S15: =ROUND(S12*'Drivers & Assumptions'!C8,0) -> 296 | T15: =ROUND(T12*'Drivers & Assumptions'!C8,0) -> 310 | U15: =ROUND(U12*'Drivers & Assumptions'!C8,0) -> 326 | V15: =ROUND(V12*'Drivers & Assumptions'!C8,0) -> 342 | W15: =ROUND(W12*'Drivers & Assumptions'!C8,0) -> 359 | X15: =ROUND(X12*'Drivers & Assumptions'!C8,0) -> 377 | Y15: =ROUND(Y12*'Drivers & Assumptions'!C8,0) -> 396 | Z15: =ROUND(Z12*'Drivers & Assumptions'!C8,0) -> 416 | AA15: =ROUND(AA12*'Drivers & Assumptions'!C8,0) -> 436 | AB15: =ROUND(AB12*'Drivers & Assumptions'!C8,0) -> 458 | AC15: =ROUND(AC12*'Drivers & Assumptions'!C8,0) -> 481 | AD15: =ROUND(AD12*'Drivers & Assumptions'!C8,0) -> 505 | AE15: =ROUND(AE12*'Drivers & Assumptions'!C8,0) -> 531 | AF15: =ROUND(AF12*'Drivers & Assumptions'!C8,0) -> 557 | AG15: =ROUND(AG12*'Drivers & Assumptions'!C8,0) -> 585 | AH15: =ROUND(AH12*'Drivers & Assumptions'!C8,0) -> 614 | AI15: =ROUND(AI12*'Drivers & Assumptions'!C8,0) -> 645 | AJ15: =ROUND(AJ12*'Drivers & Assumptions'!C8,0) -> 677 | AK15: =ROUND(AK12*'Drivers & Assumptions'!C8,0) -> 711 | AL15: =ROUND(AL12*'Drivers & Assumptions'!C8,0) -> 747 | AM15: =ROUND(AM12*'Drivers & Assumptions'!C8,0) -> 784 | AN15: =ROUND(AN12*'Drivers & Assumptions'!C8,0) -> 823 | AO15: =ROUND(AO12*'Drivers & Assumptions'!C8,0) -> 864 | AP15: =ROUND(AP12*'Drivers & Assumptions'!C8,0) -> 908 | AQ15: =ROUND(AQ12*'Drivers & Assumptions'!C8,0) -> 953 | AR15: =ROUND(AR12*'Drivers & Assumptions'!C8,0) -> 1001 | AS15: =ROUND(AS12*'Drivers & Assumptions'!C8,0) -> 1051 | AT15: =ROUND(AT12*'Drivers & Assumptions'!C8,0) -> 1103 | AU15: =ROUND(AU12*'Drivers & Assumptions'!C8,0) -> 1158 | AV15: =ROUND(AV12*'Drivers & Assumptions'!C8,0) -> 1216 | AW15: =ROUND(AW12*'Drivers & Assumptions'!C8,0) -> 1277 | AX15: =ROUND(AX12*'Drivers & Assumptions'!C8,0) -> 1341 | AY15: =ROUND(AY12*'Drivers & Assumptions'!C8,0) -> 1408 | AZ15: =ROUND(AZ12*'Drivers & Assumptions'!C8,0) -> 1478 | BA15: =ROUND(BA12*'Drivers & Assumptions'!C8,0) -> 1552 | BB15: =ROUND(BB12*'Drivers & Assumptions'!C8,0) -> 1630 | BC15: =ROUND(BC12*'Drivers & Assumptions'!C8,0) -> 1712 | BD15: =ROUND(BD12*'Drivers & Assumptions'!C8,0) -> 1797 | BE15: =ROUND(BE12*'Drivers & Assumptions'!C8,0) -> 1887 | BF15: =ROUND(BF12*'Drivers & Assumptions'!C8,0) -> 1981 | BG15: =ROUND(BG12*'Drivers & Assumptions'!C8,0) -> 2080 | BH15: =ROUND(BH12*'Drivers & Assumptions'!C8,0) -> 2184 | BI15: =ROUND(BI12*'Drivers & Assumptions'!C8,0) -> 2294
A16: New One-off Buyers | K16: =K12-K15 -> 150 | L16: =L12-L15 -> 315 | M16: =M12-M15 -> 331 | N16: =N12-N15 -> 347 | O16: =O12-O15 -> 365 | P16: =P12-P15 -> 383 | Q16: =Q12-Q15 -> 402 | R16: =R12-R15 -> 422 | ... BI16: =BI12-BI15 -> 3440
A17: Active Subscribers (end of month) | J17: 67 | K17: =ROUND(J17*(1-'Drivers & Assumptions'!C9),0)+K15 -> 160 | L17: =ROUND(K17*(1-'Drivers & Assumptions'!C9),0)+L15 -> 354 | M17: =ROUND(L17*(1-'Drivers & Assumptions'!C9),0)+M15 -> 539 | N17: =ROUND(M17*(1-'Drivers & Assumptions'!C9),0)+N15 -> 717 | O17: =ROUND(N17*(1-'Drivers & Assumptions'!C9),0)+O15 -> 888 | P17: =ROUND(O17*(1-'Drivers & Assumptions'!C9),0)+P15 -> 1054 | Q17: =ROUND(P17*(1-'Drivers & Assumptions'!C9),0)+Q15 -> 1217 | R17: =ROUND(Q17*(1-'Drivers & Assumptions'!C9),0)+R15 -> 1377 | S17: =ROUND(R17*(1-'Drivers & Assumptions'!C9),0)+S15 -> 1535 | T17: =ROUND(S17*(1-'Drivers & Assumptions'!C9),0)+T15 -> 1692 | U17: =ROUND(T17*(1-'Drivers & Assumptions'!C9),0)+U15 -> 1849 | V17: =ROUND(U17*(1-'Drivers & Assumptions'!C9),0)+V15 -> 2006 | W17: =ROUND(V17*(1-'Drivers & Assumptions'!C9),0)+W15 -> 2164 | X17: =ROUND(W17*(1-'Drivers & Assumptions'!C9),0)+X15 -> 2325 | Y17: =ROUND(X17*(1-'Drivers & Assumptions'!C9),0)+Y15 -> 2489 | Z17: =ROUND(Y17*(1-'Drivers & Assumptions'!C9),0)+Z15 -> 2656 | AA17: =ROUND(Z17*(1-'Drivers & Assumptions'!C9),0)+AA15 -> 2826 | AB17: =ROUND(AA17*(1-'Drivers & Assumptions'!C9),0)+AB15 -> 3001 | AC17: =ROUND(AB17*(1-'Drivers & Assumptions'!C9),0)+AC15 -> 3182 | AD17: =ROUND(AC17*(1-'Drivers & Assumptions'!C9),0)+AD15 -> 3369 | AE17: =ROUND(AD17*(1-'Drivers & Assumptions'!C9),0)+AE15 -> 3563 | AF17: =ROUND(AE17*(1-'Drivers & Assumptions'!C9),0)+AF15 -> 3764 | AG17: =ROUND(AF17*(1-'Drivers & Assumptions'!C9),0)+AG15 -> 3973 | AH17: =ROUND(AG17*(1-'Drivers & Assumptions'!C9),0)+AH15 -> 4190 | AI17: =ROUND(AH17*(1-'Drivers & Assumptions'!C9),0)+AI15 -> 4416 | AJ17: =ROUND(AI17*(1-'Drivers & Assumptions'!C9),0)+AJ15 -> 4651 | AK17: =ROUND(AJ17*(1-'Drivers & Assumptions'!C9),0)+AK15 -> 4897 | AL17: =ROUND(AK17*(1-'Drivers & Assumptions'!C9),0)+AL15 -> 5154 | AM17: =ROUND(AL17*(1-'Drivers & Assumptions'!C9),0)+AM15 -> 5423 | AN17: =ROUND(AM17*(1-'Drivers & Assumptions'!C9),0)+AN15 -> 5704 | AO17: =ROUND(AN17*(1-'Drivers & Assumptions'!C9),0)+AO15 -> 5998 | AP17: =ROUND(AO17*(1-'Drivers & Assumptions'!C9),0)+AP15 -> 6306 | AQ17: =ROUND(AP17*(1-'Drivers & Assumptions'!C9),0)+AQ15 -> 6628 | AR17: =ROUND(AQ17*(1-'Drivers & Assumptions'!C9),0)+AR15 -> 6966 | AS17: =ROUND(AR17*(1-'Drivers & Assumptions'!C9),0)+AS15 -> 7320 | AT17: =ROUND(AS17*(1-'Drivers & Assumptions'!C9),0)+AT15 -> 7691 | AU17: =ROUND(AT17*(1-'Drivers & Assumptions'!C9),0)+AU15 -> 8080 | AV17: =ROUND(AU17*(1-'Drivers & Assumptions'!C9),0)+AV15 -> 8488 | AW17: =ROUND(AV17*(1-'Drivers & Assumptions'!C9),0)+AW15 -> 8916 | AX17: =ROUND(AW17*(1-'Drivers & Assumptions'!C9),0)+AX15 -> 9365 | AY17: =ROUND(AX17*(1-'Drivers & Assumptions'!C9),0)+AY15 -> 9837 | AZ17: =ROUND(AY17*(1-'Drivers & Assumptions'!C9),0)+AZ15 -> 10331 | BA17: =ROUND(AZ17*(1-'Drivers & Assumptions'!C9),0)+BA15 -> 10850 | BB17: =ROUND(BA17*(1-'Drivers & Assumptions'!C9),0)+BB15 -> 11395 | BC17: =ROUND(BB17*(1-'Drivers & Assumptions'!C9),0)+BC15 -> 11968 | BD17: =ROUND(BC17*(1-'Drivers & Assumptions'!C9),0)+BD15 -> 12568 | BE17: =ROUND(BD17*(1-'Drivers & Assumptions'!C9),0)+BE15 -> 13198 | BF17: =ROUND(BE17*(1-'Drivers & Assumptions'!C9),0)+BF15 -> 13859 | BG17: =ROUND(BF17*(1-'Drivers & Assumptions'!C9),0)+BG15 -> 14553 | BH17: =ROUND(BG17*(1-'Drivers & Assumptions'!C9),0)+BH15 -> 15282 | BI17: =ROUND(BH17*(1-'Drivers & Assumptions'!C9),0)+BI15 -> 16048
A18: Cumulative One-off Pool | J18: 586 | K18: =J18+K16 -> 736 | L18: =K18+L16 -> 1051 | M18: =L18+M16 -> 1382 | N18: =M18+N16 -> 1729 | O18: =N18+O16 -> 2094 | P18: =O18+P16 -> 2477 | Q18: =P18+Q16 -> 2879 | R18: =Q18+R16 -> 3301 | ... BI18: =BH18+BI16 -> 66686
A19: Repeat One-off Orders | K19: =ROUND(K18*'Drivers & Assumptions'!C10,0) -> 37 | L19: =ROUND(L18*'Drivers & Assumptions'!C10,0) -> 53 | M19: =ROUND(M18*'Drivers & Assumptions'!C10,0) -> 69 | N19: =ROUND(N18*'Drivers & Assumptions'!C10,0) -> 86 | O19: =ROUND(O18*'Drivers & Assumptions'!C10,0) -> 105 | P19: =ROUND(P18*'Drivers & Assumptions'!C10,0) -> 124 | Q19: =ROUND(Q18*'Drivers & Assumptions'!C10,0) -> 144 | R19: =ROUND(R18*'Drivers & Assumptions'!C10,0) -> 165 | S19: =ROUND(S18*'Drivers & Assumptions'!C10,0) -> 187 | T19: =ROUND(T18*'Drivers & Assumptions'!C10,0) -> 211 | U19: =ROUND(U18*'Drivers & Assumptions'!C10,0) -> 235 | V19: =ROUND(V18*'Drivers & Assumptions'!C10,0) -> 261 | W19: =ROUND(W18*'Drivers & Assumptions'!C10,0) -> 288 | X19: =ROUND(X18*'Drivers & Assumptions'!C10,0) -> 316 | Y19: =ROUND(Y18*'Drivers & Assumptions'!C10,0) -> 346 | Z19: =ROUND(Z18*'Drivers & Assumptions'!C10,0) -> 377 | AA19: =ROUND(AA18*'Drivers & Assumptions'!C10,0) -> 409 | AB19: =ROUND(AB18*'Drivers & Assumptions'!C10,0) -> 444 | AC19: =ROUND(AC18*'Drivers & Assumptions'!C10,0) -> 480 | AD19: =ROUND(AD18*'Drivers & Assumptions'!C10,0) -> 518 | AE19: =ROUND(AE18*'Drivers & Assumptions'!C10,0) -> 558 | AF19: =ROUND(AF18*'Drivers & Assumptions'!C10,0) -> 599 | AG19: =ROUND(AG18*'Drivers & Assumptions'!C10,0) -> 643 | AH19: =ROUND(AH18*'Drivers & Assumptions'!C10,0) -> 689 | AI19: =ROUND(AI18*'Drivers & Assumptions'!C10,0) -> 738 | AJ19: =ROUND(AJ18*'Drivers & Assumptions'!C10,0) -> 789 | AK19: =ROUND(AK18*'Drivers & Assumptions'!C10,0) -> 842 | AL19: =ROUND(AL18*'Drivers & Assumptions'!C10,0) -> 898 | AM19: =ROUND(AM18*'Drivers & Assumptions'!C10,0) -> 957 | AN19: =ROUND(AN18*'Drivers & Assumptions'!C10,0) -> 1019 | AO19: =ROUND(AO18*'Drivers & Assumptions'!C10,0) -> 1083 | AP19: =ROUND(AP18*'Drivers & Assumptions'!C10,0) -> 1151 | AQ19: =ROUND(AQ18*'Drivers & Assumptions'!C10,0) -> 1223 | AR19: =ROUND(AR18*'Drivers & Assumptions'!C10,0) -> 1298 | AS19: =ROUND(AS18*'Drivers & Assumptions'!C10,0) -> 1377 | AT19: =ROUND(AT18*'Drivers & Assumptions'!C10,0) -> 1459 | AU19: =ROUND(AU18*'Drivers & Assumptions'!C10,0) -> 1546 | AV19: =ROUND(AV18*'Drivers & Assumptions'!C10,0) -> 1638 | AW19: =ROUND(AW18*'Drivers & Assumptions'!C10,0) -> 1733 | AX19: =ROUND(AX18*'Drivers & Assumptions'!C10,0) -> 1834 | AY19: =ROUND(AY18*'Drivers & Assumptions'!C10,0) -> 1940 | AZ19: =ROUND(AZ18*'Drivers & Assumptions'!C10,0) -> 2050 | BA19: =ROUND(BA18*'Drivers & Assumptions'!C10,0) -> 2167 | BB19: =ROUND(BB18*'Drivers & Assumptions'!C10,0) -> 2289 | BC19: =ROUND(BC18*'Drivers & Assumptions'!C10,0) -> 2418 | BD19: =ROUND(BD18*'Drivers & Assumptions'!C10,0) -> 2552 | BE19: =ROUND(BE18*'Drivers & Assumptions'!C10,0) -> 2694 | BF19: =ROUND(BF18*'Drivers & Assumptions'!C10,0) -> 2842 | BG19: =ROUND(BG18*'Drivers & Assumptions'!C10,0) -> 2998 | BH19: =ROUND(BH18*'Drivers & Assumptions'!C10,0) -> 3162 | BI19: =ROUND(BI18*'Drivers & Assumptions'!C10,0) -> 3334
A21: DTC TOTALS
A22: Subscription Orders | B22: =B17 -> 0 | C22: =C17 -> 0 | D22: =D17 -> 0 | E22: =E17 -> 0 | F22: =F17 -> 0 | G22: =G17 -> 0 | H22: =H17 -> 0 | I22: =I17 -> 0 | ... BI22: =BI17 -> 16048
A23: New One-off Orders | B23: =B16 -> 0 | C23: =C16 -> 0 | D23: =D16 -> 0 | E23: =E16 -> 0 | F23: =F16 -> 0 | G23: =G16 -> 0 | H23: =H16 -> 0 | I23: =I16 -> 0 | ... BI23: =BI16 -> 3440
A24: Repeat One-off Orders | B24: =B19 -> 0 | C24: =C19 -> 0 | D24: =D19 -> 0 | E24: =E19 -> 0 | F24: =F19 -> 0 | G24: =G19 -> 0 | H24: =H19 -> 0 | I24: =I19 -> 0 | ... BI24: =BI19 -> 3334
A25: Total DTC Orders | B25: =B22+B23+B24 -> 0 | C25: =C22+C23+C24 -> 0 | D25: =D22+D23+D24 -> 0 | E25: =E22+E23+E24 -> 0 | F25: =F22+F23+F24 -> 0 | G25: =G22+G23+G24 -> 0 | H25: =H22+H23+H24 -> 0 | I25: =I22+I23+I24 -> 0 | ... BI25: =BI22+BI23+BI24 -> 22822
A27: DTC Modelled Revenue (Orders × AOV) | B27: =B25*'Drivers & Assumptions'!C6 -> 0 | C27: =C25*'Drivers & Assumptions'!C6 -> 0 | D27: =D25*'Drivers & Assumptions'!C6 -> 0 | E27: =E25*'Drivers & Assumptions'!C6 -> 0 | F27: =F25*'Drivers & Assumptions'!C6 -> 0 | G27: =G25*'Drivers & Assumptions'!C6 -> 0 | H27: =H25*'Drivers & Assumptions'!C6 -> 0 | I27: =I25*'Drivers & Assumptions'!C6 -> 0 | J27: =J25*'Drivers & Assumptions'!C6 -> 8442 | K27: =K25*'Drivers & Assumptions'!C6 -> 43722 | L27: =L25*'Drivers & Assumptions'!C6 -> 90972 | M27: =M25*'Drivers & Assumptions'!C6 -> 118314 | N27: =N25*'Drivers & Assumptions'!C6 -> 144900 | O27: =O25*'Drivers & Assumptions'!C6 -> 171108 | P27: =P25*'Drivers & Assumptions'!C6 -> 196686 | Q27: =Q25*'Drivers & Assumptions'!C6 -> 222138 | R27: =R25*'Drivers & Assumptions'!C6 -> 247464 | S27: =S25*'Drivers & Assumptions'!C6 -> 272790 | T27: =T25*'Drivers & Assumptions'!C6 -> 298494 | U27: =U25*'Drivers & Assumptions'!C6 -> 324072 | V27: =V25*'Drivers & Assumptions'!C6 -> 350280 | W27: =W25*'Drivers & Assumptions'!C6 -> 376866 | X27: =X25*'Drivers & Assumptions'!C6 -> 404082 | Y27: =Y25*'Drivers & Assumptions'!C6 -> 432054 | Z27: =Z25*'Drivers & Assumptions'!C6 -> 460656 | AA27: =AA25*'Drivers & Assumptions'!C6 -> 490140 | AB27: =AB25*'Drivers & Assumptions'!C6 -> 520758 | AC27: =AC25*'Drivers & Assumptions'!C6 -> 552384 | AD27: =AD25*'Drivers & Assumptions'!C6 -> 585270 | AE27: =AE25*'Drivers & Assumptions'!C6 -> 619542 | AF27: =AF25*'Drivers & Assumptions'!C6 -> 655074 | AG27: =AG25*'Drivers & Assumptions'!C6 -> 692244 | AH27: =AH25*'Drivers & Assumptions'!C6 -> 730926 | AI27: =AI25*'Drivers & Assumptions'!C6 -> 771372 | AJ27: =AJ25*'Drivers & Assumptions'!C6 -> 813456 | AK27: =AK25*'Drivers & Assumptions'!C6 -> 857556 | AL27: =AL25*'Drivers & Assumptions'!C6 -> 903672 | AM27: =AM25*'Drivers & Assumptions'!C6 -> 952056 | AN27: =AN25*'Drivers & Assumptions'!C6 -> 1002708 | AO27: =AO25*'Drivers & Assumptions'!C6 -> 1055628 | AP27: =AP25*'Drivers & Assumptions'!C6 -> 1111068 | AQ27: =AQ25*'Drivers & Assumptions'!C6 -> 1169280 | AR27: =AR25*'Drivers & Assumptions'!C6 -> 1230390 | AS27: =AS25*'Drivers & Assumptions'!C6 -> 1294398 | AT27: =AT25*'Drivers & Assumptions'!C6 -> 1361430 | AU27: =AU25*'Drivers & Assumptions'!C6 -> 1431864 | AV27: =AV25*'Drivers & Assumptions'!C6 -> 1505826 | AW27: =AW25*'Drivers & Assumptions'!C6 -> 1583190 | AX27: =AX25*'Drivers & Assumptions'!C6 -> 1664460 | AY27: =AY25*'Drivers & Assumptions'!C6 -> 1750014 | AZ27: =AZ25*'Drivers & Assumptions'!C6 -> 1839474 | BA27: =BA25*'Drivers & Assumptions'!C6 -> 1933596 | BB27: =BB25*'Drivers & Assumptions'!C6 -> 2032254 | BC27: =BC25*'Drivers & Assumptions'!C6 -> 2136078 | BD27: =BD25*'Drivers & Assumptions'!C6 -> 2244816 | BE27: =BE25*'Drivers & Assumptions'!C6 -> 2358972 | BF27: =BF25*'Drivers & Assumptions'!C6 -> 2478798 | BG27: =BG25*'Drivers & Assumptions'!C6 -> 2604672 | BH27: =BH25*'Drivers & Assumptions'!C6 -> 2736846 | BI27: =BI25*'Drivers & Assumptions'!C6 -> 2875572
A29: DTC REVENUE (Actuals then Model)
A30: DTC Revenue (AUD) | B30: =B7 -> 37954 | C30: =C7 -> 61361 | D30: =D7 -> 108804 | E30: =E7 -> 57522 | F30: =F7 -> 71229 | G30: =G7 -> 61780 | H30: =H7 -> 62159 | I30: =I7 -> 181457 | J30: =J7 -> 50000 | K30: =K27 -> 43722 | L30: =L27 -> 90972 | M30: =M27 -> 118314 | N30: =N27 -> 144900 | O30: =O27 -> 171108 | P30: =P27 -> 196686 | Q30: =Q27 -> 222138 | R30: =R27 -> 247464 | ... BI30: =BI27 -> 2875572
A31: DTC Total Orders (for COGS calc) | B31: =B8 -> 301 | C31: =C8 -> 487 | D31: =D8 -> 864 | E31: =E8 -> 457 | F31: =F8 -> 565 | G31: =G8 -> 490 | H31: =H8 -> 493 | I31: =I8 -> 1440 | J31: =J25 -> 67 | K31: =K25 -> 347 | L31: =L25 -> 722 | M31: =M25 -> 939 | N31: =N25 -> 1150 | O31: =O25 -> 1358 | P31: =P25 -> 1561 | Q31: =Q25 -> 1763 | ... BI31: =BI25 -> 22822

Sheet Wholesale by Country
A1: PLASMAIDE — Wholesale Revenue by Country
A2: Distributor orders by country — enter actuals in blue cells, model fills forward
B4: Jul-25 | C4: Aug-25 | D4: Sep-25 | E4: Oct-25 | F4: Nov-25 | G4: Dec-25 | H4: Jan-26 | I4: Feb-26 | J4: Mar-26 | K4: Apr-26 | L4: May-26 | M4: Jun-26 | N4: Jul-26 | O4: Aug-26 | P4: Sep-26 | Q4: Oct-26 | R4: Nov-26 | S4: Dec-26 | T4: Jan-27 | U4: Feb-27 | V4: Mar-27 | W4: Apr-27 | X4: May-27 | Y4: Jun-27 | Z4: Jul-27 | AA4: Aug-27 | AB4: Sep-27 | AC4: Oct-27 | AD4: Nov-27 | AE4: Dec-27 | AF4: Jan-28 | AG4: Feb-28 | AH4: Mar-28 | AI4: Apr-28 | AJ4: May-28 | AK4: Jun-28 | AL4: Jul-28 | AM4: Aug-28 | AN4: Sep-28 | AO4: Oct-28 | AP4: Nov-28 | AQ4: Dec-28 | AR4: Jan-29 | AS4: Feb-29 | AT4: Mar-29 | AU4: Apr-29 | AV4: May-29 | AW4: Jun-29 | AX4: Jul-29 | AY4: Aug-29 | AZ4: Sep-29 | BA4: Oct-29 | BB4: Nov-29 | BC4: Dec-29 | BD4: Jan-30 | BE4: Feb-30 | BF4: Mar-30 | BG4: Apr-30 | BH4: May-30 | BI4: Jun-30
A6: WHOLESALE ORDERS BY COUNTRY (Cases per month — enter actuals, model fills forward)
A7: Australia — Cases Ordered | B7: 0 | C7: 0 | D7: 0 | E7: 0 | F7: 0 | G7: 0 | H7: 0 | I7: 0 | J7: =IF(MOD(9,'Drivers & Assumptions'!C26)=0,ROUND('Drivers & Assumptions'!C27*(1+'Drivers & Assumptions'!C28)^0,0),0) -> 5 | K7: =IF(MOD(10,'Drivers & Assumptions'!C26)=0,ROUND('Drivers & Assumptions'!C27*(1+'Drivers & Assumptions'!C28)^0,0),0) -> 0 | L7: =IF(MOD(11,'Drivers & Assumptions'!C26)=0,ROUND('Drivers & Assumptions'!C27*(1+'Drivers & Assumptions'!C28)^0,0),0) -> 0 | M7: =IF(MOD(12,'Drivers & Assumptions'!C26)=0,ROUND('Drivers & Assumptions'!C27*(1+'Drivers & Assumptions'!C28)^0,0),0) -> 5 | N7: =IF(MOD(13,'Drivers & Assumptions'!C26)=0,ROUND('Drivers & Assumptions'!C27*(1+'Drivers & Assumptions'!C28)^1,0),0) -> 0 | O7: =IF(MOD(14,'Drivers & Assumptions'!C26)=0,ROUND('Drivers & Assumptions'!C27*(1+'Drivers & Assumptions'!C28)^1,0),0) -> 0 | P7: =IF(MOD(15,'Drivers & Assumptions'!C26)=0,ROUND('Drivers & Assumptions'!C27*(1+'Drivers & Assumptions'!C28)^1,0),0) -> 6 | Q7: =IF(MOD(16,'Drivers & Assumptions'!C26)=0,ROUND('Drivers & Assumptions'!C27*(1+'Drivers & Assumptions'!C28)^1,0),0) -> 0 | R7: =IF(MOD(17,'Drivers & Assumptions'!C26)=0,ROUND('Drivers & Assumptions'!C27*(1+'Drivers & Assumptions'!C28)^1,0),0) -> 0 | S7: =IF(MOD(18,'Drivers & Assumptions'!C26)=0,ROUND('Drivers & Assumptions'!C27*(1+'Drivers & Assumptions'!C28)^1,0),0) -> 6 | T7: =IF(MOD(19,'Drivers & Assumptions'!C26)=0,ROUND('Drivers & Assumptions'!C27*(1+'Drivers & Assumptions'!C28)^1,0),0) -> 0 | U7: =IF(MOD(20,'Drivers & Assumptions'!C26)=0,ROUND('Drivers & Assumptions'!C27*(1+'Drivers & Assumptions'!C28)^1,0),0) -> 0 | V7: =IF(MOD(21,'Drivers & Assumptions'!C26)=0,ROUND('Drivers & Assumptions'!C27*(1+'Drivers & Assumptions'!C28)^1,0),0) -> 6 | W7: =IF(MOD(22,'Drivers & Assumptions'!C26)=0,ROUND('Drivers & Assumptions'!C27*(1+'Drivers & Assumptions'!C28)^1,0),0) -> 0 | X7: =IF(MOD(23,'Drivers & Assumptions'!C26)=0,ROUND('Drivers & Assumptions'!C27*(1+'Drivers & Assumptions'!C28)^1,0),0) -> 0 | Y7: =IF(MOD(24,'Drivers & Assumptions'!C26)=0,ROUND('Drivers & Assumptions'!C27*(1+'Drivers & Assumptions'!C28)^1,0),0) -> 6 | Z7: =IF(MOD(25,'Drivers & Assumptions'!C26)=0,ROUND('Drivers & Assumptions'!C27*(1+'Drivers & Assumptions'!C28)^2,0),0) -> 0 | AA7: =IF(MOD(26,'Drivers & Assumptions'!C26)=0,ROUND('Drivers & Assumptions'!C27*(1+'Drivers & Assumptions'!C28)^2,0),0) -> 0 | AB7: =IF(MOD(27,'Drivers & Assumptions'!C26)=0,ROUND('Drivers & Assumptions'!C27*(1+'Drivers & Assumptions'!C28)^2,0),0) -> 8 | AC7: =IF(MOD(28,'Drivers & Assumptions'!C26)=0,ROUND('Drivers & Assumptions'!C27*(1+'Drivers & Assumptions'!C28)^2,0),0) -> 0 | AD7: =IF(MOD(29,'Drivers & Assumptions'!C26)=0,ROUND('Drivers & Assumptions'!C27*(1+'Drivers & Assumptions'!C28)^2,0),0) -> 0 | AE7: =IF(MOD(30,'Drivers & Assumptions'!C26)=0,ROUND('Drivers & Assumptions'!C27*(1+'Drivers & Assumptions'!C28)^2,0),0) -> 8 | AF7: =IF(MOD(31,'Drivers & Assumptions'!C26)=0,ROUND('Drivers & Assumptions'!C27*(1+'Drivers & Assumptions'!C28)^2,0),0) -> 0 | AG7: =IF(MOD(32,'Drivers & Assumptions'!C26)=0,ROUND('Drivers & Assumptions'!C27*(1+'Drivers & Assumptions'!C28)^2,0),0) -> 0 | AH7: =IF(MOD(33,'Drivers & Assumptions'!C26)=0,ROUND('Drivers & Assumptions'!C27*(1+'Drivers & Assumptions'!C28)^2,0),0) -> 8 | AI7: =IF(MOD(34,'Drivers & Assumptions'!C26)=0,ROUND('Drivers & Assumptions'!C27*(1+'Drivers & Assumptions'!C28)^2,0),0) -> 0 | AJ7: =IF(MOD(35,'Drivers & Assumptions'!C26)=0,ROUND('Drivers & Assumptions'!C27*(1+'Drivers & Assumptions'!C28)^2,0),0) -> 0 | AK7: =IF(MOD(36,'Drivers & Assumptions'!C26)=0,ROUND('Drivers & Assumptions'!C27*(1+'Drivers & Assumptions'!C28)^2,0),0) -> 8 | AL7: =IF(MOD(37,'Drivers & Assumptions'!C26)=0,ROUND('Drivers & Assumptions'!C27*(1+'Drivers & Assumptions'!C28)^3,0),0) -> 0 | AM7: =IF(MOD(38,'Drivers & Assumptions'!C26)=0,ROUND('Drivers & Assumptions'!C27*(1+'Drivers & Assumptions'!C28)^3,0),0) -> 0 | AN7: =IF(MOD(39,'Drivers & Assumptions'!C26)=0,ROUND('Drivers & Assumptions'!C27*(1+'Drivers & Assumptions'!C28)^3,0),0) -> 10 | AO7: =IF(MOD(40,'Drivers & Assumptions'!C26)=0,ROUND('Drivers & Assumptions'!C27*(1+'Drivers & Assumptions'!C28)^3,0),0) -> 0 | AP7: =IF(MOD(41,'Drivers & Assumptions'!C26)=0,ROUND('Drivers & Assumptions'!C27*(1+'Drivers & Assumptions'!C28)^3,0),0) -> 0 | AQ7: =IF(MOD(42,'Drivers & Assumptions'!C26)=0,ROUND('Drivers & Assumptions'!C27*(1+'Drivers & Assumptions'!C28)^3,0),0) -> 10 | AR7: =IF(MOD(43,'Drivers & Assumptions'!C26)=0,ROUND('Drivers & Assumptions'!C27*(1+'Drivers & Assumptions'!C28)^3,0),0) -> 0 | AS7: =IF(MOD(44,'Drivers & Assumptions'!C26)=0,ROUND('Drivers & Assumptions'!C27*(1+'Drivers & Assumptions'!C28)^3,0),0) -> 0 | AT7: =IF(MOD(45,'Drivers & Assumptions'!C26)=0,ROUND('Drivers & Assumptions'!C27*(1+'Drivers & Assumptions'!C28)^3,0),0) -> 10 | AU7: =IF(MOD(46,'Drivers & Assumptions'!C26)=0,ROUND('Drivers & Assumptions'!C27*(1+'Drivers & Assumptions'!C28)^3,0),0) -> 0 | AV7: =IF(MOD(47,'Drivers & Assumptions'!C26)=0,ROUND('Drivers & Assumptions'!C27*(1+'Drivers & Assumptions'!C28)^3,0),0) -> 0 | AW7: =IF(MOD(48,'Drivers & Assumptions'!C26)=0,ROUND('Drivers & Assumptions'!C27*(1+'Drivers & Assumptions'!C28)^3,0),0) -> 10 | AX7: =IF(MOD(49,'Drivers & Assumptions'!C26)=0,ROUND('Drivers & Assumptions'!C27*(1+'Drivers & Assumptions'!C28)^4,0),0) -> 0 | AY7: =IF(MOD(50,'Drivers & Assumptions'!C26)=0,ROUND('Drivers & Assumptions'!C27*(1+'Drivers & Assumptions'!C28)^4,0),0) -> 0 | AZ7: =IF(MOD(51,'Drivers & Assumptions'!C26)=0,ROUND('Drivers & Assumptions'!C27*(1+'Drivers & Assumptions'!C28)^4,0),0) -> 12 | BA7: =IF(MOD(52,'Drivers & Assumptions'!C26)=0,ROUND('Drivers & Assumptions'!C27*(1+'Drivers & Assumptions'!C28)^4,0),0) -> 0 | BB7: =IF(MOD(53,'Drivers & Assumptions'!C26)=0,ROUND('Drivers & Assumptions'!C27*(1+'Drivers & Assumptions'!C28)^4,0),0) -> 0 | BC7: =IF(MOD(54,'Drivers & Assumptions'!C26)=0,ROUND('Drivers & Assumptions'!C27*(1+'Drivers & Assumptions'!C28)^4,0),0) -> 12 | BD7: =IF(MOD(55,'Drivers & Assumptions'!C26)=0,ROUND('Drivers & Assumptions'!C27*(1+'Drivers & Assumptions'!C28)^4,0),0) -> 0 | BE7: =IF(MOD(56,'Drivers & Assumptions'!C26)=0,ROUND('Drivers & Assumptions'!C27*(1+'Drivers & Assumptions'!C28)^4,0),0) -> 0 | BF7: =IF(MOD(57,'Drivers & Assumptions'!C26)=0,ROUND('Drivers & Assumptions'!C27*(1+'Drivers & Assumptions'!C28)^4,0),0) -> 12 | BG7: =IF(MOD(58,'Drivers & Assumptions'!C26)=0,ROUND('Drivers & Assumptions'!C27*(1+'Drivers & Assumptions'!C28)^4,0),0) -> 0 | BH7: =IF(MOD(59,'Drivers & Assumptions'!C26)=0,ROUND('Drivers & Assumptions'!C27*(1+'Drivers & Assumptions'!C28)^4,0),0) -> 0 | BI7: =IF(MOD(60,'Drivers & Assumptions'!C26)=0,ROUND('Drivers & Assumptions'!C27*(1+'Drivers & Assumptions'!C28)^4,0),0) -> 12
A8: New Zealand — Cases Ordered | B8: 0 | C8: 0 | D8: 0 | E8: 0 | F8: 0 | G8: 0 | H8: 0 | I8: 0 | J8: =IF(MOD(9,'Drivers & Assumptions'!C26)=0,ROUND('Drivers & Assumptions'!C27*(1+'Drivers & Assumptions'!C28)^0,0),0) -> 5 | K8: =IF(MOD(10,'Drivers & Assumptions'!C26)=0,ROUND('Drivers & Assumptions'!C27*(1+'Drivers & Assumptions'!C28)^0,0),0) -> 0 | L8: =IF(MOD(11,'Drivers & Assumptions'!C26)=0,ROUND('Drivers & Assumptions'!C27*(1+'Drivers & Assumptions'!C28)^0,0),0) -> 0 | M8: =IF(MOD(12,'Drivers & Assumptions'!C26)=0,ROUND('Drivers & Assumptions'!C27*(1+'Drivers & Assumptions'!C28)^0,0),0) -> 5 | N8: =IF(MOD(13,'Drivers & Assumptions'!C26)=0,ROUND('Drivers & Assumptions'!C27*(1+'Drivers & Assumptions'!C28)^1,0),0) -> 0 | O8: =IF(MOD(14,'Drivers & Assumptions'!C26)=0,ROUND('Drivers & Assumptions'!C27*(1+'Drivers & Assumptions'!C28)^1,0),0) -> 0 | P8: =IF(MOD(15,'Drivers & Assumptions'!C26)=0,ROUND('Drivers & Assumptions'!C27*(1+'Drivers & Assumptions'!C28)^1,0),0) -> 6 | Q8: =IF(MOD(16,'Drivers & Assumptions'!C26)=0,ROUND('Drivers & Assumptions'!C27*(1+'Drivers & Assumptions'!C28)^1,0),0) -> 0 | R8: =IF(MOD(17,'Drivers & Assumptions'!C26)=0,ROUND('Drivers & Assumptions'!C27*(1+'Drivers & Assumptions'!C28)^1,0),0) -> 0 | S8: =IF(MOD(18,'Drivers & Assumptions'!C26)=0,ROUND('Drivers & Assumptions'!C27*(1+'Drivers & Assumptions'!C28)^1,0),0) -> 6 | T8: =IF(MOD(19,'Drivers & Assumptions'!C26)=0,ROUND('Drivers & Assumptions'!C27*(1+'Drivers & Assumptions'!C28)^1,0),0) -> 0 | U8: =IF(MOD(20,'Drivers & Assumptions'!C26)=0,ROUND('Drivers & Assumptions'!C27*(1+'Drivers & Assumptions'!C28)^1,0),0) -> 0 | V8: =IF(MOD(21,'Drivers & Assumptions'!C26)=0,ROUND('Drivers & Assumptions'!C27*(1+'Drivers & Assumptions'!C28)^1,0),0) -> 6 | W8: =IF(MOD(22,'Drivers & Assumptions'!C26)=0,ROUND('Drivers & Assumptions'!C27*(1+'Drivers & Assumptions'!C28)^1,0),0) -> 0 | X8: =IF(MOD(23,'Drivers & Assumptions'!C26)=0,ROUND('Drivers & Assumptions'!C27*(1+'Drivers & Assumptions'!C28)^1,0),0) -> 0 | Y8: =IF(MOD(24,'Drivers & Assumptions'!C26)=0,ROUND('Drivers & Assumptions'!C27*(1+'Drivers & Assumptions'!C28)^1,0),0) -> 6 | Z8: =IF(MOD(25,'Drivers & Assumptions'!C26)=0,ROUND('Drivers & Assumptions'!C27*(1+'Drivers & Assumptions'!C28)^2,0),0) -> 0 | AA8: =IF(MOD(26,'Drivers & Assumptions'!C26)=0,ROUND('Drivers & Assumptions'!C27*(1+'Drivers & Assumptions'!C28)^2,0),0) -> 0 | AB8: =IF(MOD(27,'Drivers & Assumptions'!C26)=0,ROUND('Drivers & Assumptions'!C27*(1+'Drivers & Assumptions'!C28)^2,0),0) -> 8 | AC8: =IF(MOD(28,'Drivers & Assumptions'!C26)=0,ROUND('Drivers & Assumptions'!C27*(1+'Drivers & Assumptions'!C28)^2,0),0) -> 0 | AD8: =IF(MOD(29,'Drivers & Assumptions'!C26)=0,ROUND('Drivers & Assumptions'!C27*(1+'Drivers & Assumptions'!C28)^2,0),0) -> 0 | AE8: =IF(MOD(30,'Drivers & Assumptions'!C26)=0,ROUND('Drivers & Assumptions'!C27*(1+'Drivers & Assumptions'!C28)^2,0),0) -> 8 | AF8: =IF(MOD(31,'Drivers & Assumptions'!C26)=0,ROUND('Drivers & Assumptions'!C27*(1+'Drivers & Assumptions'!C28)^2,0),0) -> 0 | AG8: =IF(MOD(32,'Drivers & Assumptions'!C26)=0,ROUND('Drivers & Assumptions'!C27*(1+'Drivers & Assumptions'!C28)^2,0),0) -> 0 | AH8: =IF(MOD(33,'Drivers & Assumptions'!C26)=0,ROUND('Drivers & Assumptions'!C27*(1+'Drivers & Assumptions'!C28)^2,0),0) -> 8 | AI8: =IF(MOD(34,'Drivers & Assumptions'!C26)=0,ROUND('Drivers & Assumptions'!C27*(1+'Drivers & Assumptions'!C28)^2,0),0) -> 0 | AJ8: =IF(MOD(35,'Drivers & Assumptions'!C26)=0,ROUND('Drivers & Assumptions'!C27*(1+'Drivers & Assumptions'!C28)^2,0),0) -> 0 | AK8: =IF(MOD(36,'Drivers & Assumptions'!C26)=0,ROUND('Drivers & Assumptions'!C27*(1+'Drivers & Assumptions'!C28)^2,0),0) -> 8 | AL8: =IF(MOD(37,'Drivers & Assumptions'!C26)=0,ROUND('Drivers & Assumptions'!C27*(1+'Drivers & Assumptions'!C28)^3,0),0) -> 0 | AM8: =IF(MOD(38,'Drivers & Assumptions'!C26)=0,ROUND('Drivers & Assumptions'!C27*(1+'Drivers & Assumptions'!C28)^3,0),0) -> 0 | AN8: =IF(MOD(39,'Drivers & Assumptions'!C26)=0,ROUND('Drivers & Assumptions'!C27*(1+'Drivers & Assumptions'!C28)^3,0),0) -> 10 | AO8: =IF(MOD(40,'Drivers & Assumptions'!C26)=0,ROUND('Drivers & Assumptions'!C27*(1+'Drivers & Assumptions'!C28)^3,0),0) -> 0 | AP8: =IF(MOD(41,'Drivers & Assumptions'!C26)=0,ROUND('Drivers & Assumptions'!C27*(1+'Drivers & Assumptions'!C28)^3,0),0) -> 0 | AQ8: =IF(MOD(42,'Drivers & Assumptions'!C26)=0,ROUND('Drivers & Assumptions'!C27*(1+'Drivers & Assumptions'!C28)^3,0),0) -> 10 | AR8: =IF(MOD(43,'Drivers & Assumptions'!C26)=0,ROUND('Drivers & Assumptions'!C27*(1+'Drivers & Assumptions'!C28)^3,0),0) -> 0 | AS8: =IF(MOD(44,'Drivers & Assumptions'!C26)=0,ROUND('Drivers & Assumptions'!C27*(1+'Drivers & Assumptions'!C28)^3,0),0) -> 0 | AT8: =IF(MOD(45,'Drivers & Assumptions'!C26)=0,ROUND('Drivers & Assumptions'!C27*(1+'Drivers & Assumptions'!C28)^3,0),0) -> 10 | AU8: =IF(MOD(46,'Drivers & Assumptions'!C26)=0,ROUND('Drivers & Assumptions'!C27*(1+'Drivers & Assumptions'!C28)^3,0),0) -> 0 | AV8: =IF(MOD(47,'Drivers & Assumptions'!C26)=0,ROUND('Drivers & Assumptions'!C27*(1+'Drivers & Assumptions'!C28)^3,0),0) -> 0 | AW8: =IF(MOD(48,'Drivers & Assumptions'!C26)=0,ROUND('Drivers & Assumptions'!C27*(1+'Drivers & Assumptions'!C28)^3,0),0) -> 10 | AX8: =IF(MOD(49,'Drivers & Assumptions'!C26)=0,ROUND('Drivers & Assumptions'!C27*(1+'Drivers & Assumptions'!C28)^4,0),0) -> 0 | AY8: =IF(MOD(50,'Drivers & Assumptions'!C26)=0,ROUND('Drivers & Assumptions'!C27*(1+'Drivers & Assumptions'!C28)^4,0),0) -> 0 | AZ8: =IF(MOD(51,'Drivers & Assumptions'!C26)=0,ROUND('Drivers & Assumptions'!C27*(1+'Drivers & Assumptions'!C28)^4,0),0) -> 12 | BA8: =IF(MOD(52,'Drivers & Assumptions'!C26)=0,ROUND('Drivers & Assumptions'!C27*(1+'Drivers & Assumptions'!C28)^4,0),0) -> 0 | BB8: =IF(MOD(53,'Drivers & Assumptions'!C26)=0,ROUND('Drivers & Assumptions'!C27*(1+'Drivers & Assumptions'!C28)^4,0),0) -> 0 | BC8: =IF(MOD(54,'Drivers & Assumptions'!C26)=0,ROUND('Drivers & Assumptions'!C27*(1+'Drivers & Assumptions'!C28)^4,0),0) -> 12 | BD8: =IF(MOD(55,'Drivers & Assumptions'!C26)=0,ROUND('Drivers & Assumptions'!C27*(1+'Drivers & Assumptions'!C28)^4,0),0) -> 0 | BE8: =IF(MOD(56,'Drivers & Assumptions'!C26)=0,ROUND('Drivers & Assumptions'!C27*(1+'Drivers & Assumptions'!C28)^4,0),0) -> 0 | BF8: =IF(MOD(57,'Drivers & Assumptions'!C26)=0,ROUND('Drivers & Assumptions'!C27*(1+'Drivers & Assumptions'!C28)^4,0),0) -> 12 | BG8: =IF(MOD(58,'Drivers & Assumptions'!C26)=0,ROUND('Drivers & Assumptions'!C27*(1+'Drivers & Assumptions'!C28)^4,0),0) -> 0 | BH8: =IF(MOD(59,'Drivers & Assumptions'!C26)=0,ROUND('Drivers & Assumptions'!C27*(1+'Drivers & Assumptions'!C28)^4,0),0) -> 0 | BI8: =IF(MOD(60,'Drivers & Assumptions'!C26)=0,ROUND('Drivers & Assumptions'!C27*(1+'Drivers & Assumptions'!C28)^4,0),0) -> 12
A9: United Kingdom — Cases Ordered | B9: 0 | C9: 0 | D9: 0 | E9: 0 | F9: 0 | G9: 0 | H9: 0 | I9: 0 | J9: =IF(MOD(9,'Drivers & Assumptions'!C26)=0,ROUND('Drivers & Assumptions'!C27*(1+'Drivers & Assumptions'!C28)^0,0),0) -> 5 | K9: =IF(MOD(10,'Drivers & Assumptions'!C26)=0,ROUND('Drivers & Assumptions'!C27*(1+'Drivers & Assumptions'!C28)^0,0),0) -> 0 | L9: =IF(MOD(11,'Drivers & Assumptions'!C26)=0,ROUND('Drivers & Assumptions'!C27*(1+'Drivers & Assumptions'!C28)^0,0),0) -> 0 | M9: =IF(MOD(12,'Drivers & Assumptions'!C26)=0,ROUND('Drivers & Assumptions'!C27*(1+'Drivers & Assumptions'!C28)^0,0),0) -> 5 | N9: =IF(MOD(13,'Drivers & Assumptions'!C26)=0,ROUND('Drivers & Assumptions'!C27*(1+'Drivers & Assumptions'!C28)^1,0),0) -> 0 | O9: =IF(MOD(14,'Drivers & Assumptions'!C26)=0,ROUND('Drivers & Assumptions'!C27*(1+'Drivers & Assumptions'!C28)^1,0),0) -> 0 | P9: =IF(MOD(15,'Drivers & Assumptions'!C26)=0,ROUND('Drivers & Assumptions'!C27*(1+'Drivers & Assumptions'!C28)^1,0),0) -> 6 | Q9: =IF(MOD(16,'Drivers & Assumptions'!C26)=0,ROUND('Drivers & Assumptions'!C27*(1+'Drivers & Assumptions'!C28)^1,0),0) -> 0 | R9: =IF(MOD(17,'Drivers & Assumptions'!C26)=0,ROUND('Drivers & Assumptions'!C27*(1+'Drivers & Assumptions'!C28)^1,0),0) -> 0 | S9: =IF(MOD(18,'Drivers & Assumptions'!C26)=0,ROUND('Drivers & Assumptions'!C27*(1+'Drivers & Assumptions'!C28)^1,0),0) -> 6 | T9: =IF(MOD(19,'Drivers & Assumptions'!C26)=0,ROUND('Drivers & Assumptions'!C27*(1+'Drivers & Assumptions'!C28)^1,0),0) -> 0 | U9: =IF(MOD(20,'Drivers & Assumptions'!C26)=0,ROUND('Drivers & Assumptions'!C27*(1+'Drivers & Assumptions'!C28)^1,0),0) -> 0 | V9: =IF(MOD(21,'Drivers & Assumptions'!C26)=0,ROUND('Drivers & Assumptions'!C27*(1+'Drivers & Assumptions'!C28)^1,0),0) -> 6 | W9: =IF(MOD(22,'Drivers & Assumptions'!C26)=0,ROUND('Drivers & Assumptions'!C27*(1+'Drivers & Assumptions'!C28)^1,0),0) -> 0 | X9: =IF(MOD(23,'Drivers & Assumptions'!C26)=0,ROUND('Drivers & Assumptions'!C27*(1+'Drivers & Assumptions'!C28)^1,0),0) -> 0 | Y9: =IF(MOD(24,'Drivers & Assumptions'!C26)=0,ROUND('Drivers & Assumptions'!C27*(1+'Drivers & Assumptions'!C28)^1,0),0) -> 6 | Z9: =IF(MOD(25,'Drivers & Assumptions'!C26)=0,ROUND('Drivers & Assumptions'!C27*(1+'Drivers & Assumptions'!C28)^2,0),0) -> 0 | AA9: =IF(MOD(26,'Drivers & Assumptions'!C26)=0,ROUND('Drivers & Assumptions'!C27*(1+'Drivers & Assumptions'!C28)^2,0),0) -> 0 | AB9: =IF(MOD(27,'Drivers & Assumptions'!C26)=0,ROUND('Drivers & Assumptions'!C27*(1+'Drivers & Assumptions'!C28)^2,0),0) -> 8 | AC9: =IF(MOD(28,'Drivers & Assumptions'!C26)=0,ROUND('Drivers & Assumptions'!C27*(1+'Drivers & Assumptions'!C28)^2,0),0) -> 0 | AD9: =IF(MOD(29,'Drivers & Assumptions'!C26)=0,ROUND('Drivers & Assumptions'!C27*(1+'Drivers & Assumptions'!C28)^2,0),0) -> 0 | AE9: =IF(MOD(30,'Drivers & Assumptions'!C26)=0,ROUND('Drivers & Assumptions'!C27*(1+'Drivers & Assumptions'!C28)^2,0),0) -> 8 | AF9: =IF(MOD(31,'Drivers & Assumptions'!C26)=0,ROUND('Drivers & Assumptions'!C27*(1+'Drivers & Assumptions'!C28)^2,0),0) -> 0 | AG9: =IF(MOD(32,'Drivers & Assumptions'!C26)=0,ROUND('Drivers & Assumptions'!C27*(1+'Drivers & Assumptions'!C28)^2,0),0) -> 0 | AH9: =IF(MOD(33,'Drivers & Assumptions'!C26)=0,ROUND('Drivers & Assumptions'!C27*(1+'Drivers & Assumptions'!C28)^2,0),0) -> 8 | AI9: =IF(MOD(34,'Drivers & Assumptions'!C26)=0,ROUND('Drivers & Assumptions'!C27*(1+'Drivers & Assumptions'!C28)^2,0),0) -> 0 | AJ9: =IF(MOD(35,'Drivers & Assumptions'!C26)=0,ROUND('Drivers & Assumptions'!C27*(1+'Drivers & Assumptions'!C28)^2,0),0) -> 0 | AK9: =IF(MOD(36,'Drivers & Assumptions'!C26)=0,ROUND('Drivers & Assumptions'!C27*(1+'Drivers & Assumptions'!C28)^2,0),0) -> 8 | AL9: =IF(MOD(37,'Drivers & Assumptions'!C26)=0,ROUND('Drivers & Assumptions'!C27*(1+'Drivers & Assumptions'!C28)^3,0),0) -> 0 | AM9: =IF(MOD(38,'Drivers & Assumptions'!C26)=0,ROUND('Drivers & Assumptions'!C27*(1+'Drivers & Assumptions'!C28)^3,0),0) -> 0 | AN9: =IF(MOD(39,'Drivers & Assumptions'!C26)=0,ROUND('Drivers & Assumptions'!C27*(1+'Drivers & Assumptions'!C28)^3,0),0) -> 10 | AO9: =IF(MOD(40,'Drivers & Assumptions'!C26)=0,ROUND('Drivers & Assumptions'!C27*(1+'Drivers & Assumptions'!C28)^3,0),0) -> 0 | AP9: =IF(MOD(41,'Drivers & Assumptions'!C26)=0,ROUND('Drivers & Assumptions'!C27*(1+'Drivers & Assumptions'!C28)^3,0),0) -> 0 | AQ9: =IF(MOD(42,'Drivers & Assumptions'!C26)=0,ROUND('Drivers & Assumptions'!C27*(1+'Drivers & Assumptions'!C28)^3,0),0) -> 10 | AR9: =IF(MOD(43,'Drivers & Assumptions'!C26)=0,ROUND('Drivers & Assumptions'!C27*(1+'Drivers & Assumptions'!C28)^3,0),0) -> 0 | AS9: =IF(MOD(44,'Drivers & Assumptions'!C26)=0,ROUND('Drivers & Assumptions'!C27*(1+'Drivers & Assumptions'!C28)^3,0),0) -> 0 | AT9: =IF(MOD(45,'Drivers & Assumptions'!C26)=0,ROUND('Drivers & Assumptions'!C27*(1+'Drivers & Assumptions'!C28)^3,0),0) -> 10 | AU9: =IF(MOD(46,'Drivers & Assumptions'!C26)=0,ROUND('Drivers & Assumptions'!C27*(1+'Drivers & Assumptions'!C28)^3,0),0) -> 0 | AV9: =IF(MOD(47,'Drivers & Assumptions'!C26)=0,ROUND('Drivers & Assumptions'!C27*(1+'Drivers & Assumptions'!C28)^3,0),0) -> 0 | AW9: =IF(MOD(48,'Drivers & Assumptions'!C26)=0,ROUND('Drivers & Assumptions'!C27*(1+'Drivers & Assumptions'!C28)^3,0),0) -> 10 | AX9: =IF(MOD(49,'Drivers & Assumptions'!C26)=0,ROUND('Drivers & Assumptions'!C27*(1+'Drivers & Assumptions'!C28)^4,0),0) -> 0 | AY9: =IF(MOD(50,'Drivers & Assumptions'!C26)=0,ROUND('Drivers & Assumptions'!C27*(1+'Drivers & Assumptions'!C28)^4,0),0) -> 0 | AZ9: =IF(MOD(51,'Drivers & Assumptions'!C26)=0,ROUND('Drivers & Assumptions'!C27*(1+'Drivers & Assumptions'!C28)^4,0),0) -> 12 | BA9: =IF(MOD(52,'Drivers & Assumptions'!C26)=0,ROUND('Drivers & Assumptions'!C27*(1+'Drivers & Assumptions'!C28)^4,0),0) -> 0 | BB9: =IF(MOD(53,'Drivers & Assumptions'!C26)=0,ROUND('Drivers & Assumptions'!C27*(1+'Drivers & Assumptions'!C28)^4,0),0) -> 0 | BC9: =IF(MOD(54,'Drivers & Assumptions'!C26)=0,ROUND('Drivers & Assumptions'!C27*(1+'Drivers & Assumptions'!C28)^4,0),0) -> 12 | BD9: =IF(MOD(55,'Drivers & Assumptions'!C26)=0,ROUND('Drivers & Assumptions'!C27*(1+'Drivers & Assumptions'!C28)^4,0),0) -> 0 | BE9: =IF(MOD(56,'Drivers & Assumptions'!C26)=0,ROUND('Drivers & Assumptions'!C27*(1+'Drivers & Assumptions'!C28)^4,0),0) -> 0 | BF9: =IF(MOD(57,'Drivers & Assumptions'!C26)=0,ROUND('Drivers & Assumptions'!C27*(1+'Drivers & Assumptions'!C28)^4,0),0) -> 12 | BG9: =IF(MOD(58,'Drivers & Assumptions'!C26)=0,ROUND('Drivers & Assumptions'!C27*(1+'Drivers & Assumptions'!C28)^4,0),0) -> 0 | BH9: =IF(MOD(59,'Drivers & Assumptions'!C26)=0,ROUND('Drivers & Assumptions'!C27*(1+'Drivers & Assumptions'!C28)^4,0),0) -> 0 | BI9: =IF(MOD(60,'Drivers & Assumptions'!C26)=0,ROUND('Drivers & Assumptions'!C27*(1+'Drivers & Assumptions'!C28)^4,0),0) -> 12
